<?xml version="1.0" ?>
<robot xmlns:xacro="http://ros.org/wiki/xacro">

  <xacro:macro name="ur5_joints_links">

    <!-- links: main serial chain -->

    <link name="world" />

    <link name="base_link">
      <visual>
        <origin rpy="0 0 3.141592653589793" xyz="0 0 0" />
        <geometry>
          <mesh filename="package://ur5_description/meshes/visual/base.dae" />
        </geometry>
        <material name="LightGrey">
          <color rgba="0.7 0.7 0.7 1.0" />
        </material>
      </visual>
      <collision>
        <origin rpy="0 0 3.141592653589793" xyz="0 0 0" />
        <geometry>
          <mesh filename="package://ur5_description/meshes/collision/base.stl" />
        </geometry>
      </collision>
      <inertial>
        <mass value="4.0" />
        <origin rpy="0 0 0" xyz="0 0 0" />
        <inertia ixx="0.00443333156" ixy="0.0" ixz="0.0" iyy="0.00443333156" iyz="0.0" izz="0.0072" />
      </inertial>
    </link>

    <link name="shoulder_link">
      <visual>
        <origin rpy="0 0 3.141592653589793" xyz="0 0 0" />
        <geometry>
          <mesh filename="package://ur5_description/meshes/visual/shoulder.dae" />
        </geometry>
        <material name="LightGrey">
          <color rgba="0.7 0.7 0.7 1.0" />
        </material>
      </visual>
      <collision>
        <origin rpy="0 0 3.141592653589793" xyz="0 0 0" />
        <geometry>
          <mesh filename="package://ur5_description/meshes/collision/shoulder.stl" />
        </geometry>
      </collision>
      <inertial>
        <mass value="3.7" />
        <origin rpy="0 0 0" xyz="0 0 0" />
        <inertia ixx="0.010267495893" ixy="0.0" ixz="0.0" iyy="0.010267495893" iyz="0.0"
          izz="0.00666" />
      </inertial>
    </link>

    <link name="upper_arm_link">
      <visual>
        <origin rpy="1.5707963267948966 0 -1.5707963267948966" xyz="0 0 0.138" />
        <geometry>
          <mesh filename="package://ur5_description/meshes/visual/upperarm.dae" />
        </geometry>
        <material name="LightGrey">
          <color rgba="0.7 0.7 0.7 1.0" />
        </material>
      </visual>
      <collision>
        <origin rpy="1.5707963267948966 0 -1.5707963267948966" xyz="0 0 0.138" />
        <geometry>
          <mesh filename="package://ur5_description/meshes/collision/upperarm.stl" />
        </geometry>
      </collision>
      <inertial>
        <mass value="8.393" />
        <origin rpy="0 1.5707963267948966 0" xyz="-0.2125 0.0 0.138" />
        <inertia ixx="0.1338857818623325" ixy="0.0" ixz="0.0" iyy="0.1338857818623325" iyz="0.0"
          izz="0.0151074" />
      </inertial>
    </link>

    <link name="forearm_link">
      <visual>
        <origin rpy="1.5707963267948966 0 -1.5707963267948966" xyz="0 0 0.007" />
        <geometry>
          <mesh filename="package://ur5_description/meshes/visual/forearm.dae" />
        </geometry>
        <material name="LightGrey">
          <color rgba="0.7 0.7 0.7 1.0" />
        </material>
      </visual>
      <collision>
        <origin rpy="1.5707963267948966 0 -1.5707963267948966" xyz="0 0 0.007" />
        <geometry>
          <mesh filename="package://ur5_description/meshes/collision/forearm.stl" />
        </geometry>
      </collision>
      <inertial>
        <mass value="2.275" />
        <origin rpy="0 1.5707963267948966 0" xyz="-0.1961 0.0 0.007" />
        <inertia ixx="0.031209355099586295" ixy="0.0" ixz="0.0" iyy="0.031209355099586295" iyz="0.0"
          izz="0.004095" />
      </inertial>
    </link>

    <link name="wrist_1_link">
      <visual>
        <origin rpy="1.5707963267948966 0 0" xyz="0 0 -0.127" />
        <geometry>
          <mesh filename="package://ur5_description/meshes/visual/wrist1.dae" />
        </geometry>
        <material name="LightGrey">
          <color rgba="0.7 0.7 0.7 1.0" />
        </material>
      </visual>
      <collision>
        <origin rpy="1.5707963267948966 0 0" xyz="0 0 -0.127" />
        <geometry>
          <mesh filename="package://ur5_description/meshes/collision/wrist1.stl" />
        </geometry>
      </collision>
      <inertial>
        <mass value="1.219" />
        <origin rpy="0 0 0" xyz="0 0 0" />
        <inertia ixx="0.0025598989760400002" ixy="0.0" ixz="0.0" iyy="0.0025598989760400002"
          iyz="0.0" izz="0.0021942" />
      </inertial>
    </link>

    <link name="wrist_2_link">
      <visual>
        <origin rpy="0 0 0" xyz="0 0 -0.0997" />
        <geometry>
          <mesh filename="package://ur5_description/meshes/visual/wrist2.dae" />
        </geometry>
        <material name="LightGrey">
          <color rgba="0.7 0.7 0.7 1.0" />
        </material>
      </visual>
      <collision>
        <origin rpy="0 0 0" xyz="0 0 -0.0997" />
        <geometry>
          <mesh filename="package://ur5_description/meshes/collision/wrist2.stl" />
        </geometry>
      </collision>
      <inertial>
        <mass value="1.219" />
        <origin rpy="0 0 0" xyz="0 0 0" />
        <inertia ixx="0.0025598989760400002" ixy="0.0" ixz="0.0" iyy="0.0025598989760400002"
          iyz="0.0" izz="0.0021942" />
      </inertial>
    </link>
    
    <link name="wrist_3_link">
      <visual>
        <origin rpy="1.5707963267948966 0 0" xyz="0 0 -0.0989" />
        <geometry>
          <mesh filename="package://ur5_description/meshes/visual/wrist3.dae" />
        </geometry>
        <material name="LightGrey">
          <color rgba="0.7 0.7 0.7 1.0" />
        </material>
      </visual>
      <collision>
        <origin rpy="1.5707963267948966 0 0" xyz="0 0 -0.0989" />
        <geometry>
          <mesh filename="package://ur5_description/meshes/collision/wrist3.stl" />
        </geometry>
      </collision>
      <inertial>
        <mass value="0.1879" />
        <origin rpy="0 0 0" xyz="0.0 0.0 -0.0229" />
        <inertia ixx="9.890410052167731e-05" ixy="0.0" ixz="0.0" iyy="9.890410052167731e-05"
          iyz="0.0" izz="0.0001321171875" />
      </inertial>
    </link>

    <!-- joints: main serial chain -->

    <joint name="base_fixed_joint" type="fixed">
      <parent link="world"/>
      <child link="base_link"/>
      <origin xyz="0 0 0" rpy="0 0 0"/>
    </joint>

    <joint name="joint1" type="revolute">
      <parent link="base_link" />
      <child link="shoulder_link" />
      <origin rpy="0 0 0" xyz="0 0 0.1625" />
      <axis xyz="0 0 1" />
      <limit effort="150.0" lower="-6.283185307179586" upper="6.283185307179586"
        velocity="3.141592653589793" />
    </joint>

    <joint name="joint2" type="revolute">
      <parent link="shoulder_link" />
      <child link="upper_arm_link" />
      <origin rpy="1.5707 1.5707 0" xyz="0 0 0" />
      <axis xyz="0 0 1" />
      <limit effort="150.0" lower="-6.283185307179586" upper="6.283185307179586"
        velocity="3.141592653589793" />
    </joint>

    <joint name="joint3" type="revolute">
      <parent link="upper_arm_link" />
      <child link="forearm_link" />
      <origin rpy="0 0 0" xyz="-0.425 0 0" />
      <axis xyz="0 0 1" />
      <limit effort="150.0" lower="-3.141592653589793" upper="3.141592653589793"
        velocity="3.141592653589793" />
    </joint>

    <joint name="joint4" type="revolute">
      <parent link="forearm_link" />
      <child link="wrist_1_link" />
      <origin rpy="0 0 -1.5707" xyz="-0.3922 0 0.1333" />
      <axis xyz="0 0 1" />
      <limit effort="28.0" lower="-6.283185307179586" upper="6.283185307179586"
        velocity="3.141592653589793" />
    </joint>

    <joint name="joint5" type="revolute">
      <parent link="wrist_1_link" />
      <child link="wrist_2_link" />
      <origin rpy="1.570796327 0 0" xyz="0 -0.0997 -2.044881182297852e-11" />
      <axis xyz="0 0 1" />
      <limit effort="28.0" lower="-6.283185307179586" upper="6.283185307179586"
        velocity="3.141592653589793" />
    </joint>

    <joint name="joint6" type="revolute">
      <parent link="wrist_2_link" />
      <child link="wrist_3_link" />
      <origin rpy="1.570796326589793 3.141592653589793 3.141592653589793"
        xyz="0 0.0996 -2.042830148012698e-11" />
      <axis xyz="0 0 1" />
      <limit effort="28.0" lower="-6.283185307179586" upper="6.283185307179586"
        velocity="3.141592653589793" />
    </joint>


  </xacro:macro>

</robot>
